Traceback (most recent call last):
  File "C:\Users\chanc\Desktop\ZIA FINAL PROJECT\EASF\Lib\site-packages\jupyter_cache\executors\utils.py", line 58, in single_nb_execution
    executenb(
  File "C:\Users\chanc\Desktop\ZIA FINAL PROJECT\EASF\Lib\site-packages\nbclient\client.py", line 1319, in execute
    return NotebookClient(nb=nb, resources=resources, km=km, **kwargs).execute()
           ^^^^^^^^^^^^^^^^^^^^^^^^^^^^^^^^^^^^^^^^^^^^^^^^^^^^^^^^^^^^^^^^^^^^^
  File "C:\Users\chanc\Desktop\ZIA FINAL PROJECT\EASF\Lib\site-packages\jupyter_core\utils\__init__.py", line 165, in wrapped
    return loop.run_until_complete(inner)
           ^^^^^^^^^^^^^^^^^^^^^^^^^^^^^^
  File "C:\Users\chanc\AppData\Local\Programs\Python\Python312\Lib\asyncio\base_events.py", line 685, in run_until_complete
    return future.result()
           ^^^^^^^^^^^^^^^
  File "C:\Users\chanc\Desktop\ZIA FINAL PROJECT\EASF\Lib\site-packages\nbclient\client.py", line 709, in async_execute
    await self.async_execute_cell(
  File "C:\Users\chanc\Desktop\ZIA FINAL PROJECT\EASF\Lib\site-packages\nbclient\client.py", line 1062, in async_execute_cell
    await self._check_raise_for_error(cell, cell_index, exec_reply)
  File "C:\Users\chanc\Desktop\ZIA FINAL PROJECT\EASF\Lib\site-packages\nbclient\client.py", line 918, in _check_raise_for_error
    raise CellExecutionError.from_cell_and_msg(cell, exec_reply_content)
nbclient.exceptions.CellExecutionError: An error occurred while executing the following cell:
------------------
def normalize_data(filename):
    patient_data = []
    diabetic_pred = []
    with open(filename, 'r') as file:
        lines = file.readlines()
    
    for line in lines:
        patient_data.append(line.strip().split(',')[0:9])

    for line in lines:
        diabetic_pred.append(line.strip().split(',')[0:10:9])
    
    return (patient_data, diabetic_pred)

patient_data, diabetic_pred = normalize_data('diabetes.csv')

db_file = 'normalized.db'
------------------


[1;31m---------------------------------------------------------------------------[0m
[1;31mFileNotFoundError[0m                         Traceback (most recent call last)
Cell [1;32mIn[2], line 15[0m
[0;32m     11[0m         diabetic_pred[38;5;241m.[39mappend(line[38;5;241m.[39mstrip()[38;5;241m.[39msplit([38;5;124m'[39m[38;5;124m,[39m[38;5;124m'[39m)[[38;5;241m0[39m:[38;5;241m10[39m:[38;5;241m9[39m])
[0;32m     13[0m     [38;5;28;01mreturn[39;00m (patient_data, diabetic_pred)
[1;32m---> 15[0m patient_data, diabetic_pred [38;5;241m=[39m [43mnormalize_data[49m[43m([49m[38;5;124;43m'[39;49m[38;5;124;43mdiabetes.csv[39;49m[38;5;124;43m'[39;49m[43m)[49m
[0;32m     17[0m db_file [38;5;241m=[39m [38;5;124m'[39m[38;5;124mnormalized.db[39m[38;5;124m'[39m

Cell [1;32mIn[2], line 4[0m, in [0;36mnormalize_data[1;34m(filename)[0m
[0;32m      2[0m patient_data [38;5;241m=[39m []
[0;32m      3[0m diabetic_pred [38;5;241m=[39m []
[1;32m----> 4[0m [38;5;28;01mwith[39;00m [38;5;28;43mopen[39;49m[43m([49m[43mfilename[49m[43m,[49m[43m [49m[38;5;124;43m'[39;49m[38;5;124;43mr[39;49m[38;5;124;43m'[39;49m[43m)[49m [38;5;28;01mas[39;00m file:
[0;32m      5[0m     lines [38;5;241m=[39m file[38;5;241m.[39mreadlines()
[0;32m      7[0m [38;5;28;01mfor[39;00m line [38;5;129;01min[39;00m lines:

File [1;32m~\Desktop\ZIA FINAL PROJECT\EASF\Lib\site-packages\IPython\core\interactiveshell.py:324[0m, in [0;36m_modified_open[1;34m(file, *args, **kwargs)[0m
[0;32m    317[0m [38;5;28;01mif[39;00m file [38;5;129;01min[39;00m {[38;5;241m0[39m, [38;5;241m1[39m, [38;5;241m2[39m}:
[0;32m    318[0m     [38;5;28;01mraise[39;00m [38;5;167;01mValueError[39;00m(
[0;32m    319[0m         [38;5;124mf[39m[38;5;124m"[39m[38;5;124mIPython won[39m[38;5;124m'[39m[38;5;124mt let you open fd=[39m[38;5;132;01m{[39;00mfile[38;5;132;01m}[39;00m[38;5;124m by default [39m[38;5;124m"[39m
[0;32m    320[0m         [38;5;124m"[39m[38;5;124mas it is likely to crash IPython. If you know what you are doing, [39m[38;5;124m"[39m
[0;32m    321[0m         [38;5;124m"[39m[38;5;124myou can use builtins[39m[38;5;124m'[39m[38;5;124m open.[39m[38;5;124m"[39m
[0;32m    322[0m     )
[1;32m--> 324[0m [38;5;28;01mreturn[39;00m [43mio_open[49m[43m([49m[43mfile[49m[43m,[49m[43m [49m[38;5;241;43m*[39;49m[43margs[49m[43m,[49m[43m [49m[38;5;241;43m*[39;49m[38;5;241;43m*[39;49m[43mkwargs[49m[43m)[49m

[1;31mFileNotFoundError[0m: [Errno 2] No such file or directory: 'diabetes.csv'

